Workbook

Sheet Summary
A2: MODULE | B2: TOTAL TEST | C2: PASSED | D2: FAILED | E2: UNEXECUTED | F2: BLOCKED | G2: NOT APPLICABLE | H2: %NOT TESTED | I2: % PASSED | J2: % FAILED | K2: % COMPLETION
A3: Vehicle Management | B3: =SUM(C3:E3) -> 12 | C3: =COUNTIF('Vehicle Management'!I:I,Summary!C2) -> 10 | D3: =COUNTIF('Vehicle Management'!I:I,Summary!D2) -> 2 | E3: =COUNTIF('Vehicle Management'!I:I,Summary!E2) -> 0 | F3: =COUNTIF('Vehicle Management'!I:I,Summary!F2) -> 0 | G3: =COUNTIF('Vehicle Management'!I:I,Summary!G2) -> 0 | H3: =IFERROR(E3/(B3),0) -> 0 | I3: =IFERROR(C3/(B3),0) -> 0.83333333 | J3: =IFERROR(D3/(B3),0) -> 0.16666667 | K3: =IFERROR((C3+D3)/B3, 0) -> 1
A4: Parking Reservation | B4: =SUM(C4:E4) -> 17 | C4: =COUNTIF('Parking Reservation'!I:I,C2) -> 14 | D4: =COUNTIF('Parking Reservation'!I:I,D2) -> 3 | E4: =COUNTIF('Parking Reservation'!I:I,E2) -> 0 | F4: =COUNTIF('Parking Reservation'!I:I,F2) -> 1 | G4: =COUNTIF('Parking Reservation'!I:I,G2) -> 0 | H4: =IFERROR(E4/(B4),0) -> 0 | I4: =IFERROR(C4/(B4),0) -> 0.82352941 | J4: =IFERROR(D4/(B4),0) -> 0.17647059 | K4: =IFERROR((C4+D4)/B4, 0) -> 1
A5: Building Management | B5: =SUM(C5:E5) -> 21 | C5: =COUNTIF('Building Management'!I:I,C2) -> 20 | D5: =COUNTIF('Building Management'!I:I,D2) -> 1 | E5: =COUNTIF('Building Management'!I:I,E2) -> 0 | F5: =COUNTIF('Building Management'!I:I,F2) -> 0 | G5: =COUNTIF('Building Management'!I:I,G2) -> 0 | H5: =IFERROR(E5/(B5),0) -> 0 | I5: =IFERROR(C5/(B5),0) -> 0.95238095 | J5: =IFERROR(D5/(B5),0) -> 0.047619048 | K5: =IFERROR((C5+D5)/(B5), 0) -> 1
A6: Parking Config | B6: =SUM(C6:E6) -> 17 | C6: =COUNTIF('Parking Config'!I:I,C2) -> 15 | D6: =COUNTIF('Parking Config'!I:I,D2) -> 2 | E6: =COUNTIF('Parking Config'!I:I,E2) -> 0 | F6: =COUNTIF('Parking Config'!I:I,F2) -> 1 | G6: =COUNTIF('Parking Config'!I:I,G2) -> 0 | H6: =IFERROR(E6/(B6),0) -> 0 | I6: =IFERROR(C6/(B6),0) -> 0.88235294 | J6: =IFERROR(D6/(B6),0) -> 0.11764706 | K6: =IFERROR((C6+D6)/B6, 0) -> 1
A7: Parking Attendant | B7: =SUM(C7:E7) -> 17 | C7: =COUNTIF('Parking Attendant'!I:I,C2) -> 11 | D7: =COUNTIF('Parking Attendant'!I:I,D2) -> 1 | E7: =COUNTIF('Parking Attendant'!I:I,E2) -> 5 | F7: =COUNTIF('Parking Attendant'!I:I,F2) -> 0 | G7: =COUNTIF('Parking Attendant'!I:I,G2) -> 0 | H7: =IFERROR(E7/(B7),0) -> 0.29411765 | I7: =IFERROR(C7/(B7),0) -> 0.64705882 | J7: =IFERROR(D7/(B7),0) -> 0.058823529 | K7: =IFERROR((C7+D7)/B7, 0) -> 0.70588235
A8: Attendant Management | B8: =SUM(C8:E8) -> 11 | C8: =COUNTIF('Attendant Management'!I:I,Summary!C2) -> 9 | D8: =COUNTIF('Attendant Management'!I:I,Summary!D2) -> 2 | E8: =COUNTIF('Attendant Management'!I:I,Summary!E2) -> 0 | F8: =COUNTIF('Attendant Management'!I:I,Summary!F2) -> 0 | G8: =COUNTIF('Attendant Management'!I:I,Summary!G2) -> 0 | H8: =IFERROR(E8/(B8),0) -> 0 | I8: =IFERROR(C8/(B8),0) -> 0.81818182 | J8: =IFERROR(D8/(B8),0) -> 0.18181818 | K8: =IFERROR((C8+D8)/B8, 0) -> 1
A9: Zone Management | B9: =SUM(C9:E9) -> 15 | C9: =COUNTIF('Zone Management'!I:I,Summary!C2) -> 14 | D9: =COUNTIF('Zone Management'!I:I,Summary!D2) -> 1 | E9: =COUNTIF('Zone Management'!I:I,Summary!E2) -> 0 | F9: =COUNTIF('Zone Management'!I:I,Summary!F2) -> 0 | G9: =COUNTIF('Zone Management'!I:I,Summary!G2) -> 0 | H9: =IFERROR(E9/(B9),0) -> 0 | I9: =IFERROR(C9/(B9),0) -> 0.93333333 | J9: =IFERROR(D9/(B9),0) -> 0.066666667 | K9: =IFERROR((C9+D9)/B9, 0) -> 1
A10: Building Policies | B10: =SUM(C10:E10) -> 17 | C10: =COUNTIF('Building Policies'!I:I,Summary!C2) -> 15 | D10: =COUNTIF('Building Policies'!I:I,Summary!D2) -> 2 | E10: =COUNTIF('Building Policies'!I:I,Summary!E2) -> 0 | F10: =COUNTIF('Building Policies'!I:I,Summary!F2) -> 0 | G10: =COUNTIF('Building Policies'!I:I,Summary!G2) -> 0 | H10: =IFERROR(E10/(B10),0) -> 0 | I10: =IFERROR(C10/(B10),0) -> 0.88235294 | J10: =IFERROR(D10/(B10),0) -> 0.11764706 | K10: =IFERROR((C10+D10)/B10, 0) -> 1
A11: Total | B11: =C11+D11+E11+F11 -> 129 | C11: =SUM(C3:C10) -> 108 | D11: =SUM(D3:D10) -> 14 | E11: =SUM(E3:E10) -> 5 | F11: =SUM(F3:F10) -> 2 | G11: =SUM(G3:G9) -> 0 | H11: =AVERAGE(H3:H10) -> 0.036764706 | I11: =AVERAGE(I3:I10) -> 0.84656544 | J11: =AVERAGE(J3:J10) -> 0.11666985 | K11: =IFERROR((C11+D11+F11)/B11, 0) -> 0.96124031
A12: LEGEND | C12: Testing Exit Criteria Met ( Atleast 80% Pass rate and Completion rate, NO open defects)
C13: Partial Testing Exit Criteria Met ( Atleast 80% Pass rate and Completion rate AND Has no P1 or P2 defects)
C14: Testing Exit Criteria Not Met ( Below 80% Pass rate and Completion rate OR has Open P1 and P2 Defects)

Sheet Vehicle Management
A1: TEST CASE ID | B1: MODULE | C1: TEST CASE | D1: PREREQUISITES | E1: TEST STEPS | F1: TEST DATA | G1: EXPECTED RESULT | H1: ACTUAL RESULT | I1: STATUS | J1: DATE EXECUTED | K1: TESTER | L1: REMARKS
A2: TCID-VEHICLE-MANAGEMENT-001 | B2: Vehicle Management | C2: Verify that User can successfully access and the page thru the mobile browser | E2: 1. Upon login thru the mobile browser, click Vehicles tab | G2: Vehicle page should display | H2: As expected | I2: Passed | J2: 46085 | K2: Adrian
A3: TCID-VEHICLE-MANAGEMENT-002 | B3: Vehicle Management | C3: Verify that User can successfully navigate in the Add Vehicle page from the Dashboard | E3: 1. Upon login, click the Add Vehicle under My Vehicles | G3: Add Your Vehicle pop up page will display | H3: As expected | I3: Passed | J3: 46079 | K3: Rose
A4: TCID-VEHICLE-MANAGEMENT-003 | B4: Vehicle Management | C4: Verify that User can successfully add a new vehicle | E4: 1. Upon login, click the Add Vehicle under My Vehicles 2. Enter Plate Number 3. Enter Make 4. Enter Model 5. Enter Color 6. Click Save Vehicle | F4: Plate Number: ABC 1234 Make: Toyota Model: Corolla Color: Black | G4: Add Your Vehicle pop up page will close and will display "Vehicle Added! You can now book a parking slot" pop up message, redirecting User back to Dashboard with the newly added vehicle under My Vehicle | H4: As expected | I4: Passed | J4: 46079 | K4: Rose
A5: TCID-VEHICLE-MANAGEMENT-004 | B5: Vehicle Management | C5: Verify that User won’t be able to add a new vehicle if plate number field is not filled in | E5: 1. Upon login, click Manage on My Vehicles 2. Click Add Vehicle 3. Leave Plate Number blank 4. Enter Make 5. Enter Model 6. Enter Color 7. Click Save Vehicle | F5: Make: Toyota Model: Vios Color: Black | G5: Please fill in this field text field error message will display | H5: As expected | I5: Passed | J5: 46079 | K5: Rose
A6: TCID-VEHICLE-MANAGEMENT-005 | B6: Vehicle Management | C6: Verify that User can successfully add a new vehicle if only the plate number field is filled in | E6: 1. Upon login, click Manage on My Vehicles 2. Click Add Vehicle 3. Enter Plate Number 4. Click Save Vehicle | F6: Plate Number: GHI 456 | G6: Add Your Vehicle pop up page will close and will display "Vehicle Added successfully!" pop up message, redirecting User back to My Vehicles page with newly added vehicle | H6: As expected | I6: Passed | J6: 46079 | K6: Rose
A7: TCID-VEHICLE-MANAGEMENT-007 | B7: Vehicle Management | C7: Verify that User will not be able to add a new vehicle if User didn't meet the field requirements | E7: 1. Upon login, click Manage on My Vehicles 2. Click Add Vehicle 3. Enter Plate Number 4. Enter Make 5. Enter Model 6. Enter Color 7. Click Save Vehicle | I7: Failed | J7: 46080 | K7: Adrian | L7: PPA-34
A8: TCID-VEHICLE-MANAGEMENT-008 | B8: Vehicle Management | C8: Verify that User will not be able to add a new vehicle if User exceeded the field requirements | E8: 1. Upon login, click Manage on My Vehicles 2. Click Add Vehicle 3. Enter Plate Number 4. Enter Make 5. Enter Model 6. Enter Color 7. Click Save Vehicle | I8: Failed | J8: 46080 | K8: Adrian | L8: PPA-33
A9: TCID-VEHICLE-MANAGEMENT-009 | B9: Vehicle Management | C9: Verify that User will not be able to add a vehicle upon losing internet connection during adding | E9: 1. Upon login, click Manage on My Vehicles 2. Turn off wifi 3. Click Add Vehicle 4. Enter Plate Number 5. Enter Make 6. Enter Model 7. Enter Color 8. Click Save Vehicle | G9: "Failed to add vehicle" popup message should display and should not add Vehicle | H9: As expected | I9: Passed | J9: 46085 | K9: Rose
A10: TCID-VEHICLE-MANAGEMENT-010 | B10: Vehicle Management | C10: Verify that User can leave the Add Vehicle page and details will not be saved | E10: 1. Upon login, click Manage on My Vehicles 2. Turn off wifi 3. Click Add Vehicle 4. Enter Plate Number 5. Enter Make 6. Enter Model 7. Enter Color 8. Cancel the workflow | G10: Vehicle not added | H10: As expected | I10: Passed | J10: 46083 | K10: Adrian
A11: TCID-VEHICLE-MANAGEMENT-011 | B11: Vehicle Management | C11: Verify that User can successfully delete a vehicle with no active reservations | E11: 1. Upon login, click Manage on My Vehicles 2. Click the delete icon on the selected vehicle 3. Click OK | G11: "Vehicle deleted" pop up message should display and should successully delete the vehicle | H11: As expected | I11: Passed | J11: 46079 | K11: Rose | L11: PPA-32
A12: TCID-VEHICLE-MANAGEMENT-012 | B12: Vehicle Management | C12: Verify that User can cancel deleting a vehicle | E12: 1. Upon login, click Manage on My Vehicles 2. Click the delete icon on the selected vehicle 3. Click Cancel | G12: Pop up confirmation page should disappear and vehicle should not be deleted | H12: As expected | I12: Passed | J12: 46079 | K12: Rose
A13: TCID-VEHICLE-MANAGEMENT-014 | B13: Vehicle Management | C13: Verify that User will not be able to delete a vehicle upon losing internet connection | E13: 1. Upon login, click Manage on My Vehicles 2. Turn off wifi 3. Click the delete icon on the selected vehicle 4. Click Cancel | G13: "Failed to delete vehicle" pop up message should display and vehicle should not be deleted | H13: As expected | I13: Passed | J13: 46085 | K13: Rose

Sheet Parking Reservation
A1: TEST CASE ID | B1: MODULE | C1: TEST CASE | D1: PREREQUISITES | E1: TEST STEPS | F1: TEST DATA | G1: EXPECTED RESULT | H1: ACTUAL RESULT | I1: STATUS | J1: DATE EXECUTED | K1: TESTER | L1: REMARKS
A2: TCID-PARKING-RESERVATION-001 | C2: Verify that User can successfully book a reservation | E2: 1. Upon login, click Reserve Now 2. Select building 3. Select floor 4. Select date 5. Select hours 6. Click Confirm Booking | F2: Building: NCVI Floor: 1 Slot: 9 Date: February 27, 2026 Hours: 7am-4pm | G2: "Parking spot reserved successfully" pop up message should display and User should be redirected back to My Reservations page with the created booking reservation | H2: As expected | I2: Passed | J2: 46079 | K2: Rose
A3: TCID-PARKING-RESERVATION-002 | C3: Verify that User will not be able to book a reservation if there is no added vehicle | E3: 1. Upon login, click My Profile & Preference tab 2. Click View My Reservations 3. Under Active tab, click Book Now 4. Select building 5. Select floor 6. Select date 7. Select hours | G3: Confirm Booking button should be disabled | H3: As expected | I3: Passed | J3: 46079 | K3: Rose
A4: TCID-PARKING-RESERVATION-003 | C4: Verify that User will not be able to select a slot with active dedicated slot policy | E4: 1. Upon login, click My Profile & Preference tab 2. Select building 5. Select floor 6. Hover over a parking slot | F4: Building: Pacific Start Building Floor: Basement 1 | G4: Parking slot should be disabled and cannot be reserved by the User | H4: As expected | I4: Passed | J4: 46079 | K4: Rose
A5: TCID-PARKING-RESERVATION-004 | C5: Verify that User can add a vehicle when no vehicle exists | E5: 1. Upon login, click My Profile & Preference tab 2. Click View My Reservations 3. Under Active tab, click Book Now 4. Click Add Vehicle 5. Fill in details 6. Click Save & Continue | G5: "Vehicle added!" pop up message should display and will display the added vehicle under Select Vehicle | H5: As expected | I5: Passed | J5: 46079 | K5: Rose
A6: TCID-PARKING-RESERVATION-005 | C6: Verify that User can book multiple dates for reservation | E6: 1. Upon login, click My Profile & Preference tab 2. Click View My Reservations 3. Under Active tab, click Book Now 4. Click Add Vehicle 5. Fill in details 6. Click Save & Continue | F6: Building: NCVI Floor: 1 Slot: 9 Date: February 27-March5 Hours: 7am-4pm | G6: "Parking spot reserved successfully" pop up message should display and User should be redirected back to My Reservations page with the created booking reservations | H6: As expected | I6: Passed | J6: 46085 | K6: Rose
A7: TCID-PARKING-RESERVATION-006 | C7: Verify that User will not be allowed to book a reservation post-date | E7: 1. Upon login, click Book a Spot 2. Select building 3. Select floor 4. Hover over the post dates | G7: Dates should be disabled | H7: As expected | I7: Passed | J7: 46079 | K7: Rose
A8: TCID-PARKING-RESERVATION-007 | C8: Verify that User will not be able to select the slot that has been booked the whole day | E8: 1. Upon login, click Reserve Now 2. Select building 3. Select floor 4. Select a slot 5. Select a date | F8: Building: NCVI Floor: 1 Date: February 27 | G8: Slot should be disabled and User will not be able to booked the slot | H8: As expected | I8: Passed | J8: 46080 | K8: Rose
A9: TCID-PARKING-RESERVATION-008 | C9: Verify that User can view the QR code associated on the booking reservation from Dashboard | E9: 1. On the dashboard under My Reservations, click the QR icon on the booked reservation | G9: System should display the ff. details Booking QR Code | Exit button QR Code Present this QR code to the parking attendant | H9: As expected | I9: Passed | J9: 46080 | K9: Rose
A10: TCID-PARKING-RESERVATION-009 | C10: Verify that User can view the QR code associated on the booking reservation from View My Reservations | E10: 1. From the Dashbord, click My Profile & Preferences tab 2. Click View My Reservations 3. Click the QR icon on the booked reservation | G10: System should display the ff. details: Parking QR Code | Exit button QR Code Building Name Floor No. and Slot No. Date Reserved Time Reserved Plate Number Show this QR code to the parking attendant | H10: As expected | I10: Passed | J10: 46080 | K10: Rose
A11: TCID-PARKING-RESERVATION-010 | C11: Verify that User can delete a booked reservation from Dashboard | E11: 1. On the dashboard under My Reservations, click the x icon | G11: "Reservation cancelled" pop up message will display and will be remove under the Active tab and move to History tab | H11: As expected | I11: Passed | J11: 46080 | K11: Rose
A12: TCID-PARKING-RESERVATION-011 | C12: Verify that User can delete a booked reservation from View My Reservations | E12: 1. From the Dashbord, click My Profile & Preferences tab 2. Click View My Reservations 3. Click the x on the booked reservation | G12: "Reservation cancelled" pop up message will display and will be remove under the Active tab and move to History tab | H12: As expected | I12: Passed | J12: 46080 | K12: Rose
A13: TCID-PARKING-RESERVATION-012 | C13: Verify that the specific time will be opened if a booked reservation has been cancelled by the User | E13: 1. On the Dashboard, click Reserve Now 2. Select building 3. Select floor 4. Select a slot 5. Select a date | G13: Specific time should be available again for reservation | H13: As expected | I13: Passed | J13: 46080 | K13: Rose
A14: TCID-PARKING-RESERVATION-013 | C14: Verify that User cannot book a reservation earlier than the current time | E14: 1. Upon login, click Reserve Now 2. Select building 3. Select floor 4. Hover over today's date 5. Select earlier hours | G14: Earlier hours should be disabled | H14: Can click earlier hours and book a reservation | I14: Failed | J14: 46083 | K14: Rose | L14: PPA-37
A15: TCID-PARKING-RESERVATION-014 | C15: Verify that the specific time will be opened if a booked reservation has been cancelled by the Admin | E15: 1. On the Dashboard, click Reserve Now 2. Select building 3. Select floor 4. Select a slot 5. Select a date | G15: Specific time should be available again for reservation | H15: As expected | I15: Passed | J15: 46083 | K15: Rose
A16: TCID-PARKING-RESERVATION-015 | C16: Verify that the booking hours should be automatically selected if the Default Booking Hours/Booking Preference has been set prior to making a reservation | E16: 1. On the Dashboard, click Reserve Now 2. Select building 3. Select floor 4. Select a slot | G16: Hours should be automatically selected | H16: Default booking hours not automatically applied | I16: Failed | J16: 46084 | K16: Rose | L16: PPA-40
A17: TCID-PARKING-RESERVATION-016 | C17: Verify that the booking hours will no longer be applied if Booking Preference has been removed | E17: 1. On the Dashboard, click Reserve Now 2. Select building 3. Select floor 4. Select a slot | G17: System should allow User to select hours | I17: Blocked | J17: 46084 | K17: Rose | L17: Execute after PPA-40 has been fixed
A18: TCID-PARKING-RESERVATION-017 | C18: Verify that User can receive a notification for No-Show status | E18: 1. Login as User 2. Click the notification bell | G18: Notification should open and display full contents | H18: Unable to click the notification and view the full content | I18: Failed | J18: 46085 | K18: Rose | L18: PPA-48
A19: TCID-PARKING-RESERVATION-018 | C19: Verify that User cannot book a reservation outside his/her zone | E19: 1. On the Dashboard, click Reserve Now 2. Select building 3. Select floor 4. Select a date 5. Select a slot 6. Select hours 7. Click Confirm Booking | G19: "You are not assigned to this building's zone. Please contact your administrator" popup message should display, and should not allow User to book a reservation | H19: As expected | I19: Passed | J19: 46085 | K19: Rose

Sheet Building Management
A1: TEST CASE ID | B1: MODULE | C1: TEST CASE | D1: PREREQUISITES | E1: TEST STEPS | F1: TEST DATA | G1: EXPECTED RESULT | H1: ACTUAL RESULT | I1: STATUS | J1: DATE EXECUTED | K1: TESTER | L1: REMARKS
A2: TCID-BUILDING-MANAGEMENT-001 | B2: Buildings | C2: Verify if a parking slot can be blocked | E2: 1. Login to the admin panel 2. Click Buildings 3. Select a building 4. Select a floor 5. Select a parking slot 6. Click the X button | F2: Email: adfargas@pjlhuillier.com Role: Admin | G2: A message will be shown to the user and the slot status and color will be changed to Blocked and gray respectively "Slot ### blocked" | H2: As expected | I2: Passed | J2: 46079 | K2: Adrian
A3: TCID-BUILDING-MANAGEMENT-002 | B3: Buildings | C3: Verify if a parking slot can be unblocked | E3: 1. Login to the admin panel 2. Click Buildings 3. Select a building 4. Select a floor 5. Select a parking slot 6. Click the X button | F3: Email: adfargas@pjlhuillier.com Role: Admin | G3: A message will be shown to the user and the slot status and color will be changed to Blocked and gray respectively "Slot ### unblocked" | H3: As expected | I3: Passed | J3: 46079 | K3: Adrian
A4: TCID-BUILDING-MANAGEMENT-003 | B4: Buildings | C4: Verify that Admin can successfully add a Building | E4: 1. Login to the admin panel 2. Click Buildings 3. Click Add Building 4. Enter Building Name 5. Enter Address 6. Select a value under the Floors dropdown 7. Enter Slots/Floor 8. Enter Slot Prefix 9. Click Create Building | F4: admin0302@cebuana.com Role: Admin | G4: "Building created" popup message should display, Add New Building modal page should close and the created Building should display on the Building Management page with updates on the total count of the ff. details: Buildings Floors Total Slots Available | H4: As expected | I4: Passed | J4: 46084 | K4: Rose
A5: TCID-BUILDING-MANAGEMENT-004 | B5: Buildings | C5: Verify that Admin can search Building Name using exact characters | E5: 1. Navigate to Reservation Management 2. Click Search 3. Enter full building name | F5: User's Name: CL Tower Makati | G5: System should display result | H5: As expected | I5: Passed | J5: 46084 | K5: Rose
A6: TCID-BUILDING-MANAGEMENT-005 | B6: Buildings | C6: Verify that Admin can search Building Name using incomplete characters | E6: 1. Navigate to Reservation Management 2. Click Search 3. Enter keyword | G6: System should display result | H6: As expected | I6: Passed | J6: 46084 | K6: Rose
A7: TCID-BUILDING-MANAGEMENT-006 | B7: Buildings | C7: Verify that Admin can search Address using exact characters | E7: 1. Navigate to Reservation Management 2. Click Search 3. Enter full address | G7: System should display result | H7: As expected | I7: Passed | J7: 46084 | K7: Rose
A8: TCID-BUILDING-MANAGEMENT-007 | B8: Buildings | C8: Verify that Admin can search Address using incomplete characters | E8: 1. Navigate to Reservation Management 2. Click Search 3. Enter keyword | G8: System should display result | H8: As expected | I8: Passed | J8: 46084 | K8: Rose
A9: TCID-BUILDING-MANAGEMENT-008 | B9: Buildings | C9: Verify that Admin can add floor on existing Building | D9: TCID-BUILDING-MANAGEMENT-003 | E9: 1. Click Add Floor on selected Building 2. Enter Floor name 3. Enter Prefix 4. Enter Number of slots 5. Click Add Floor | G9: "Floor added" popup message should display, Add New Floor modal page should close and the added Floor should display under the Building added with updates on the total count of the ff. details: Floors Total Slots Available | H9: As expected | I9: Passed | J9: 46084 | K9: Rose
A10: TCID-BUILDING-MANAGEMENT-009 | B10: Buildings | C10: Verify that Admin can cancel adding a floor on existing Building | D10: TCID-BUILDING-MANAGEMENT-003 | E10: 1. Click Add Floor on selected Building 2. Enter Floor name 3. Enter Prefix 4. Enter Number of slots 5. Click Cancel | G10: Add New Floor modal page should close, with no floor added on the selected building and no updates on the total count of the ff. details: Floors Total Slots Available | H10: As expected | I10: Passed | J10: 46084 | K10: Rose
A11: TCID-BUILDING-MANAGEMENT-010 | B11: Buildings | C11: Verify that Admin can delete a Building | D11: TCID-BUILDING-MANAGEMENT-003 | E11: 1. Click the delete icon 2. Click OK | G11: "Building deleted" popup message should display, the confirmation modal message should close, the deleted Building should no longer be on the list and with updates on the total count of the ff. details: Buildings Floors Total Slots Available | H11: As expected | I11: Passed | J11: 46084 | K11: Rose
A12: TCID-BUILDING-MANAGEMENT-011 | B12: Buildings | C12: Very that Admin can cancel deleting a Building | D12: TCID-BUILDING-MANAGEMENT-003 | E12: 1. Click the delete icon 2. Click Cancel | G12: Confirmation modal page should close and the Building should not be deleted | H12: As expected | I12: Passed | J12: 46084 | K12: Rose
A13: TCID-BUILDING-MANAGEMENT-012 | B13: Buildings | C13: Verify that Admin can add slots on the existing Building | D13: TCID-BUILDING-MANAGEMENT-003 | E13: 1. Click Add Slots 2. Enter details 3. Click Add Slots | G13: "Added *count* slots" popup message should display, Add Slots to Floor modal page should close and the added Slots should display under the selected floor with updates on the total count of the ff. details: Total Slots Available | H13: As expected | I13: Passed | J13: 46084 | K13: Rose
A14: TCID-BUILDING-MANAGEMENT-013 | B14: Buildings | C14: Verify that Admin can cancel adding slots on the existing Building | E14: 1. Click Add Slots on selected Floor 2. Enter details 3. Click Cancel | G14: Add Slots to Floor modal page should close, with no slots added on the selected floor and no updates on the total count of the ff. details: Total Slots Available | H14: As expected | I14: Passed | J14: 46084 | K14: Rose
A15: TCID-BUILDING-MANAGEMENT-014 | B15: Buildings | C15: Verify that the added Building can be viewed in Zone Management module | D15: TCID-BUILDING-MANAGEMENT-003 | E15: 1. Login as Admin 2. Navigate to Zone Management 3. Edit Zone 4. Browse on the list of Buildings | F15: Building Name: CLF SM Manila | G15: Added building should display | H15: As expected | I15: Passed | J15: 46084 | K15: Rose
A16: TCID-BUILDING-MANAGEMENT-015 | B16: Buildings | C16: Verify that Admin can upload a floor layout image | D16: TCID-BUILDING-MANAGEMENT-003 | E16: 1. Click the down arrow on selected floor 2. Click Upload 3. Select Image 4. Click Open | G16: "Floor layout image uploaded" popup modal page should display, upload button should be replaced with View and Remove buttons | H16: As expected | I16: Passed | J16: 46084 | K16: Rose
A17: TCID-BUILDING-MANAGEMENT-016 | B17: Buildings | C17: Verify that Admin can update the slot's name | D17: TCID-BUILDING-MANAGEMENT-003 | E17: 1. Click a slot 2. Enter updated slot name 3. Click the check button | G17: "Slot renamed" popup message should display with the updated name reflected on the slot without any issue on the UI | H17: Slot name overlaps with the Slot UI | I17: Failed | J17: 46084 | K17: Rose | L17: PPA-43
A18: TCID-BUILDING-MANAGEMENT-017 | B18: Buildings | C18: Verify that Admin can view the Floor layout image | D18: TCID-BUILDING-MANAGEMENT-015 | E18: 1. Click the View button | G18: Floor image will display on another browser | H18: As expected | I18: Passed | J18: 46084 | K18: Rose
A19: TCID-BUILDING-MANAGEMENT-018 | B19: Buildings | C19: Verify that Admin can remove the uploaded floor layout image | D19: TCID-BUILDING-MANAGEMENT-015 | E19: 1. Click the Remove button | G19: "Layout image removed" popup message should display, View and Remove buttons should be removed and Upload button should display | H19: As expected | I19: Passed | J19: 46084 | K19: Rose
A20: TCID-BUILDING-MANAGEMENT-019 | B20: Buildings | C20: Verify that Admin can delete a slot | D20: TCID-BUILDING-MANAGEMENT-003 | E20: 1. Click the down arrow on selected floor 2. Click the x button on the slot 3. Click OK | G20: "Slot deleted" popup message should display, deleting the slot on the floor and total count of the ff. details should be updated: Total Slots Available | H20: As expected | I20: Passed | J20: 46084 | K20: Rose
A21: TCID-BUILDING-MANAGEMENT-020 | B21: Buildings | C21: Verify that Admin can cancel deleting a slot | D21: TCID-BUILDING-MANAGEMENT-003 | E21: 1. Click the down arrow on selected floor 2. Click the x button on the slot 3. Click Cancel | G21: Confirmation modal page should close and the slot should not be deleted | H21: As expected | I21: Passed | J21: 46084 | K21: Rose
A22: TCID-BUILDING-MANAGEMENT-021 | B22: Buildings | C22: Verify that Admin can't block a slot if there's already a reservation | E22: 1. Login to the admin panel 2. Click Buildings 3. Select a building 4. Select a floor 5. Select a parking slot 6. Click the X button | G22: "Cannot block a slot with active reservations. Cancel them first." popup message should display and slot should not be deleted | H22: As expected | I22: Passed | J22: 46085 | K22: Rose

Sheet Parking Config
A1: TEST CASE ID | B1: MODULE | C1: TEST CASE | D1: PREREQUISITES | E1: TEST STEPS | F1: TEST DATA | G1: EXPECTED RESULT | H1: ACTUAL RESULT | I1: STATUS | J1: DATE EXECUTED | K1: TESTER | L1: REMARKS
A2: TCID-PARKING-CONFIG-001 | B2: Parking Config | C2: Verify if the Parking Configuration module has the following elements visible in the UI: Select Building Parking Release Time Parking Hours Booking Window No-Show Slot Release Waitlist Configuration Main Building Exclusivity | E2: 1. Login to the admin panel 2. Click Parking Config | G2: All UI elements are displayed | H2: As expected | I2: Passed | J2: 46084 | K2: Adrian
A3: TCID-PARKING-CONFIG-002 | B3: Parking Config | C3: Verify if an admin can select a building to be configured | E3: 1. Login to the admin panel 2. Click Parking Config 3. Select a building | G3: Individual buildings can be selected to be edited | H3: As expected | I3: Passed | J3: 46084 | K3: Adrian
A4: TCID-PARKING-CONFIG-003 | B4: Parking Config | C4: Verify if an admin can set a no-show auto-release on a parking slot | E4: 1. Login to the admin panel 2. Click Parking Config 3. Set a Enable Auto-release to ON 4. Determine a timeframe for the auto-release 5. Save changes | F4: Email: adfargas@pjlhuillier.com Role: Admin | G4: Changes saved with message "Configuration saved successfully" | H4: As expected Save button hidden under Made with Emergent logo | I4: Passed | J4: 46080 | K4: Adrian | L4: PPA-31
A5: TCID-PARKING-CONFIG-004 | B5: Parking Config | C5: Verify if an employee can book a reservation if a building has Main Building Exclusivity active | D5: The employee is registered to the building | E5: 1. Login to the admin panel 2. Click Parking Config 3. Select a building 4. Toggle Enable Main Building Restriction under Main Building Exclusivity 5. Login as an employee 6. Process a booking under the building with the main building restriction on | G5: "Parking spot reserved successfully!" popup message should display and User should be redirected back to My reservations page with the booked reservation | H5: As expected | I5: Passed | J5: 46084 | K5: Rose
A6: TCID-PARKING-CONFIG-005 | B6: Parking Config | C6: Verify if an employee can book a reservation if a building has Main Building Exclusivity active | D6: The employee is not registered to the building | E6: 1. Login to the admin panel 2. Click Parking Config 3. Select a building 4. Toggle Enable Main Building Restriction under Main Building Exclusivity 5. Login as an employee 6. Process a booking under the building with the main building restriction on | G6: "You are not assigned to this building's zone. Please contact your administrator" popup message should display and User should not be able to book a reservation | H6: As expected | I6: Passed | J6: 46084 | K6: Adrian
A7: TCID-PARKING-CONFIG-006 | B7: Parking Config | C7: Verify if the admin can set a default parking release time | E7: 1. Login to the admin panel 2. Click Parking Config 3. Select a building 4. Set a value for the default parking release time | G7: Default parking release time assigned | H7: As expected | I7: Passed | J7: 46085 | K7: Adrian
A8: TCID-PARKING-CONFIG-007 | B8: Parking Config | C8: Verify if the parking slots will be automatically released during the set default parking release time | E8: 1. Login to the admin panel 2. Click Parking Config 3. Select a building 4. Set a value for the default parking release time 5. Verify if the parking slots for a building will be released automatically once the value for the default parking time release is reached | I8: Blocked | J8: 46085 | K8: Rose | L8: PPA-49
A9: TCID-PARKING-CONFIG-008 | B9: Parking Config | C9: Verify the admin can set a value for the number of days an advance booking is allowed | E9: 1. Login to the admin panel 2. Click Parking Config 3. Set a value for Booking Window 4. Click Save Configuration | G9: "Configuration saved successfully" popup message should display and updates the fields | H9: As expected | I9: Passed | J9: 46085 | K9: Adrian
A10: TCID-PARKING-CONFIG-009 | B10: Parking Config | C10: Verify if a user can complete a booking past the value specified in the Booking Window | E10: 1. Login to the admin panel 2. Click Parking Config 3. Set a value for Booking Window 4. Login as an employee 5. Verify if a booking can be made past the value determined in the Booking Window in the admin panel | G10: The days past the determined value (counting the current date) are locked and are not available for reservation | H10: As expected | I10: Passed | J10: 46085 | K10: Rose
A11: TCID-PARKING-CONFIG-010 | B11: Parking Config | C11: Verify if the waitlist can be toggled on and off | E11: 1. Login to the admin panel 2. Click Parking Config 3. Toggle the Enable Waitlist | G11: Waitlist enabled/disabled | H11: As expected | I11: Passed | J11: 46085 | K11: Adrian
A12: TCID-PARKING-CONFIG-011 | B12: Parking Config | C12: Verify if the admin can set a value in minutes when the users in the waitlist are notified | E12: 1. Login to the admin panel 2. Click Parking Config 3. Set a value for the notification window 4. Login as an employee 5. Reserve a slot in a fully booked building to join the waitlist 6. Verify if a notification will be sent in advance regarding the booking depending on the value set in the Notification Window | G12: User should receive a notification if the slot is opened | H12: As expected | I12: Passed | J12: 46085 | K12: Rose
A13: TCID-PARKING-CONFIG-012 | B13: Parking Config | C13: Set a default value for the default parking hours for a building | E13: 1. Login to the admin panel 2. Click Parking Config 3. Set a value under the default parking hours | I13: Passed | J13: 46085 | K13: Adrian
A14: TCID-PARKING-CONFIG-013 | B14: Parking Config | C14: Verify if a user can book a slot before the defined default parking hours | E14: 1. Login as a user 2. Attempt to process a booking before the start of the default parking hours | G14: Hours should not be selected and User should not be allowed to book a reservation within those hours | H14: Can select hours and allows User to book the reservation | I14: Failed | J14: 46085 | K14: Rose | L14: PPA-49
A15: TCID-PARKING-CONFIG-014 | B15: Parking Config | C15: Verify if a user can book a slot after the defined default parking hours | E15: 1. Login as user 2. Attempt to process a booking after the end of the default parking hours | G15: Hours should not be selected and User should not be allowed to book a reservation within those hours | H15: Can select hours and allows User to book the reservation | I15: Failed | J15: 46085 | K15: Rose | L15: PPA-49
A16: TCID-PARKING-CONFIG-015 | B16: Parking Config | C16: Verify if a user can book a slot during the duration of the defined default parking hours | E16: 1. Login as user 2. Attempt to process a booking at any given time during the duration of the default parking hours | I16: Passed | J16: 46085 | K16: Adrian
A17: TCID-PARKING-CONFIG-016 | B17: Parking Config | C17: Verify if the users in the waitlist are notified in order | E17: 1. Login as a user 2. Process a booking under a fully booked building | G17: Notification should be received | H17: As expected | I17: Passed | J17: 46085 | K17: Rose
A18: TCID-PARKING-CONFIG-017 | B18: Parking Config | C18: Verify if the changes to a building's configuration can be saved | E18: 1. Login to the admin panel 2. Select a building 3. Configure the parameters 4. Click Save | G18: Changes saved | H18: As expected | I18: Passed | J18: 46085 | K18: Adrian
A19: TCID-PARKING-CONFIG-018 | B19: Parking Config | C19: Verify if the changes to a building's configuration will be lost when the user exits Parking Config without saving | E19: 1. Login to the admin panel 2. Select a building 3. Configure the parameters 4. Exit without saving | G19: No changes were saved | H19: As expected | I19: Passed | J19: 46085 | K19: Adrian

Sheet Parking Attendant
A1: TEST CASE ID | B1: MODULE | C1: TEST CASE | D1: PREREQUISITES | E1: TEST STEPS | F1: TEST DATA | G1: EXPECTED RESULT | H1: ACTUAL RESULT | I1: STATUS | J1: DATE EXECUTED | K1: TESTER | L1: REMARKS
A2: TCID-RESERVATION-MANAGEMENT-001 | B2: Parking Attendant Dashboard | C2: Verify that an attendant can successfully confirm a booking reservation using the Confirm button | E2: 1. Login to the app using an attendant account 2. Select an active booking 3. Click Confirm | F2: Email: synthtwo@cebuana.com Role: Attendant | G2: The booking will be confirmed, status will change to Confirmed and Confirmed count should be updated | H2: As expected | I2: Passed | J2: 46079 | K2: Adrian
A3: TCID-PARKING-ATTENDANT-001 | B3: Parking Attendant Dashboard | C3: Verify that an attendant cannot tag a booking as a no-show once it has been confirmed | E3: 1. Login to the app using an attendant account 2. Select an active booking 3. Click Confirm 4. Locate the confirmed booking and tap the No-Show button | F3: Email: synthtwo@cebuana.com Role: Attendant | G3: The no-show button must either be invisible or not clickable | H3: Booking confirmed -> changed status to No-Show | I3: Failed | J3: 46079 | K3: Adrian | L3: PPA-26
A4: TCID-PARKING-ATTENDANT-001 | B4: Parking Attendant Dashboard | C4: Verify that an attendant can successfully confirm a booking reservation using the QR Code | E4: 1. Login to the app using an attendant account 2. Click the scan qr icon | G4: Attendant should successfully confirm a booking reservation and status should change from Reserved to Confirmed | H4: No options to scan a QR code | I4: Unexecuted | J4: 46080 | K4: Rose | L4: PPA-25
A5: TCID-PARKING-ATTENDANT-002 | B5: Parking Attendant Dashboard | C5: Verify that Attendant can view all bookings based on date selected | E5: 1. Login to the app using an attendant account 2. Click the date 3. Select the date | F5: Date: February 27 | G5: List of reservations should display | H5: As expected | I5: Passed | J5: 46080 | K5: Rose
A6: TCID-PARKING-ATTENDANT-003 | B6: Parking Attendant Dashboard | C6: Verify that Attendant can redirect back on today's reservation | E6: 1. Login to the app using an attendant account 2. Click the date 3. Select the date 4. Click today | G6: List of reservation for today should display with the accurate Reserved, Confirmed, and No Shows count | H6: As expected | I6: Passed | J6: 46080 | K6: Rose
A7: TCID-PARKING-ATTENDANT-004 | B7: Parking Attendant Dashboard | C7: Verify if the Scan QR button will display a pop-up dialogue that will enable the user to input a QR Code token | E7: 1. Login to the app using an attendant account 2. Click the scan qr icon | G7: The Scan QR code pop-up will be displayed | H7: As expected | I7: Passed | J7: 46083 | K7: Adrian | L7: No option to scan QR code
A8: TCID-PARKING-ATTENDANT-005 | B8: Parking Attendant Dashboard | C8: Verify if the user can input alphanumeric characters in the QR Token field in the Scan QR Code pop-up | E8: 1. Login to the app using an attendant account 2. Click the scan qr icon | G8: Alphanumeric texts are allowed | H8: As expected; no length limiter is active | I8: Passed | J8: 46083 | K8: Adrian | L8: No option to scan QR code
A9: TCID-PARKING-ATTENDANT-006 | B9: Parking Attendant Dashboard | C9: Verify if the user can validate a valid QR token | E9: 1. Login to the app using an attendant account 2. Click the scan qr icon 3. Enter a QR token 4. Click Look Up | G9: QR token validated | I9: Unexecuted | L9: No option to scan QR code
A10: TCID-PARKING-ATTENDANT-007 | B10: Parking Attendant Dashboard | C10: Verify if the user will be met with a warning or error message when attempting to validate an invalid QR token | E10: 1. Login to the app using an attendant account 2. Click the scan qr icon 3. Enter a QR token 4. Click Look Up | G10: Invalid token not accepted | H10: As expected; no length limiter is active | I10: Passed | J10: 46083 | K10: Adrian | L10: No option to scan QR code
A11: TCID-PARKING-ATTENDANT-008 | B11: Parking Attendant Dashboard | C11: Verify that the details in Dashboard will update if the Admin cancels a confirmed booking reservation | E11: 1. Login to the app using an attendant account | G11: Confirmed count should be updated and the status of the confirmed parking reservation should be updated to Cancelled | H11: As expected | I11: Passed | J11: 46083 | K11: Rose
A12: TCID-PARKING-ATTENDANT-009 | B12: Parking Attendant Dashboard | C12: Verify that the details in Dashboard will update if the Admin cancels a reserved booking reservation | E12: 1. Login to the app using an attendant account | G12: Reserved count should be updated and the status of the reserved parking reservation should be updated to Cancelled | H12: As expected | I12: Passed | J12: 46083 | K12: Rose
A13: TCID-PARKING-ATTENDANT-010 | B13: Parking Attendant Dashboard | C13: Verify that details will be updated upon edit by Admin on Attendant's details | E13: 1. Login to the website as Attendant | G13: Dashboard will display with update on ff. details: Name List of reservation | H13: As expected | I13: Passed | J13: 46083 | K13: Rose
A14: TCID-PARKING-ATTENDANT-011 | B14: Parking Attendant Dashboard | C14: Verify if the user can scan a QR code for a reservation | E14: 1. Login to the app using an attendant account 2. Click the scan qr icon 3. Scan QR code | G14: QR code scanned successfully; booking confirmed | I14: Unexecuted | J14: 46085 | K14: Adrian | L14: No option to scan QR code
A15: TCID-PARKING-ATTENDANT-012 | B15: Parking Attendant Dashboard | C15: Verify if the user can scan a QR code not intended for a reservaiton | E15: 1. Login to the app using an attendant account 2. Click the scan qr icon 3. Scan QR code | G15: QR code scan failure; booking not confirmed | I15: Unexecuted | J15: 46085 | K15: Adrian | L15: No option to scan QR code
A16: TCID-PARKING-ATTENDANT-013 | B16: Parking Attendant Dashboard | C16: Verify that Parking Attendant can filter reservations by Assigned Building | E16: 1. Login to the app using an attendant account 2. Click the building dropdown 3. Select building | G16: List of reservations under selected building should display | H16: No options to filter buildings | I16: Unexecuted | J16: 46085 | K16: Rose
A17: TCID-PARKING-ATTENDANT-014 | B17: Parking Attendant Dashboard | C17: Verify that the details in Dashboard will update if the User cancels a confirmed booking reservation | E17: 1. Login to the app using an attendant account | G17: Confirmed count should be updated and the status of the confirmed parking reservation should be updated to Cancelled | H17: As expected | I17: Passed | J17: 46085 | K17: Rose
A18: TCID-PARKING-ATTENDANT-015 | B18: Parking Attendant Dashboard | C18: Verify details if the Attendant re-scans a QR code with a Confirmed status | E18: 1. Login to the website using an attendant account 2. Click the QR code 3. Scan the QR code | G18: QR code scanned successfully, displaying details of the User and Vehicle | H18: As expected | I18: Passed | J18: 46085 | K18: Rose

Sheet Attendant Management
A1: TEST CASE ID | B1: MODULE | C1: TEST CASE | D1: PREREQUISITES | E1: TEST STEPS | F1: TEST DATA | G1: EXPECTED RESULT | H1: ACTUAL RESULT | I1: STATUS | J1: DATE EXECUTED | K1: TESTER | L1: REMARKS
A2: TCID-ATTENDANT-MANAGEMENT-001 | B2: Attendants | C2: Verify that Admin can view list of Attendants | E2: 1. Upon login, click the Attendants on the sidebar | G2: Admin will be redirected in the Parking Attendants page with the ff. details: Name Email Assigned Building Actions | H2: As expected | I2: Passed | J2: 46083 | K2: Rose
A3: TCID-ATTENDANT-MANAGEMENT-002 | B3: Attendants | C3: Verify that Admin can add a new Attendant | E3: 1. In Parking Attendants page, click Add Attendant 2. Fill in details 3. Click Create | G3: Add New Attendant modal popup page should close, "Attendant created successfully" popup page should display, and Parking Attendants page should display with the newly added Attendant | H3: As expected | I3: Passed | J3: 46083 | K3: Rose
A4: TCID-ATTENDANT-MANAGEMENT-003 | B4: Attendants | C4: Verify that Admin can cancel adding a new Attendant using the Cancel button | E4: 1. In Parking Attendants page, click Add Attendant 2. Click Cancel | G4: Add New Attendant modal popup page should close and account should not be created | H4: As expected | I4: Passed | J4: 46083 | K4: Rose
A5: TCID-ATTENDANT-MANAGEMENT-004 | B5: Attendants | C5: Verify that Admin can cancel adding a new Attendant using the close button | E5: 1. In Parking Attendants page, click Add Attendant 2. Click X | G5: Add New Attendant modal popup page should close and account should not be created | H5: As expected | I5: Passed | J5: 46083 | K5: Rose
A6: TCID-ATTENDANT-MANAGEMENT-005 | B6: Attendants | C6: Verify that Admin can successfully update Attendant's details | E6: 1. In Parking Attendants page, click the ellipses on the Attendant 2. Click Edit 3. Update details 4. Click Update | G6: Edit Attendant modal popup page should close, "Attendant updated successfully" popup page should display, and Parking Attendants page should display with the updated Attendant's details | H6: As expected | I6: Passed | J6: 46083 | K6: Rose
A7: TCID-ATTENDANT-MANAGEMENT-006 | B7: Attendants | C7: Verify that Admin can successfully delete an Attendant | E7: 1. In Parking Attendants page, click the ellipses on the Attendant 2. Click Delete 3. Click OK | G7: Confirmation modal page should close, "Attendant deleted" popup page should display, and Parking Attendants page should display without the deleted Attendant | H7: As expected | I7: Passed | J7: 46083 | K7: Rose
A8: TCID-ATTENDANT-MANAGEMENT-007 | B8: Attendants | C8: Verify that Admin cannot create an Attendant account if required fields aren't fill in | E8: 1. In Parking Attendants page, click Add Attendant 2. Fill in all details except for Assigned Building 3. Click Create | G8: Field validation should display and should not allow Admin to create an account | H8: Successfully creates Attendant account | I8: Failed | J8: 46083 | K8: Rose | L8: PPA-35
A9: TCID-ATTENDANT-MANAGEMENT-008 | B9: Attendants | C9: Verify that Attendants created from the Attendant Management page will also display in User Management page | E9: 1. Login as Admin 2. Navigate to User Management 3. Search for an Attendant created from Attendant Management page | G9: Result should display | H9: As expected | I9: Passed | J9: 46083 | K9: Rose
A10: TCID-ATTENDANT-MANAGEMENT-009 | B10: Attendants | C10: Verify that Attendants deleted from the Attendant Management page will also not display in User Management page | E10: 1. Login as Admin 2. Navigate to User Management 3. Search for an Attendant deleted from Attendant Management page | G10: Should display No users found | H10: As expected | I10: Passed | J10: 46083 | K10: Rose
A11: TCID-ATTENDANT-MANAGEMENT-010 | B11: Attendants | C11: Verify that Admin can cancel deleting an Attendant | E11: 1. In Parking Attendants page, click the ellipses on the Attendant 2. Click Delete 3. Click Cancel | G11: Confirmation modal page should close and account should not be deleted | H11: As expected | I11: Passed | J11: 46083 | K11: Rose
A12: TCID-ATTENDANT-MANAGEMENT-011 | B12: Attendants | C12: Verify that Admin can assign Attendant to multple buildings | D12: TCID-ATTENDANT-MANAGEMENT-002 | E12: 1. In Parking Attendants page, click the ellipses on the Attendant 2. Click Edit 3. Assign Attendant to multiple buildings 4. Click Update | G12: Edit Attendant modal popup page should close, "Attendant updated successfully" popup page should display, and Parking Attendants page should display with the updated Attendant's details | H12: Unable to assign Attendant to multiple buildings | I12: Failed | J12: 46085 | K12: Rose | L12: PPA-44

Sheet Zone Management
A1: TEST CASE ID | B1: MODULE | C1: TEST CASE | D1: PREREQUISITES | E1: TEST STEPS | F1: TEST DATA | G1: EXPECTED RESULT | H1: ACTUAL RESULT | I1: STATUS | J1: DATE EXECUTED | K1: TESTER | L1: REMARKS
A2: TCID-ZONE-MANAGEMENT-001 | B2: Zone Management | C2: Verify if the following UI elements can be seen in the Zone Management screen: Total Zones Buildings in Zones Assigned Users Unassigned Users Short list of Unassigned users (with total number displayed) Created Zones Create Zone button | E2: 1. Login to the admin panel 2. Click Zone Management | F2: Email: cardinal.test@cebuana.com Role: Admin | G2: UI elements displayed | H2: As expected | I2: Passed | J2: 46084 | K2: Adrian
A3: TCID-ZONE-MANAGEMENT-002 | B3: Zone Management | C3: Verify if the card for a zone displays the following information: Zone Name Total number of buildings inside the zone Edit Button Delete Button Name of buildings in the zone Total number of users registered to the zone List of users registered to the zone | E3: 1. Login to the admin panel 2. Click Zone Management | F3: Email: cardinal.test@cebuana.com Role: Admin | G3: UI elements displayed | H3: As expected | I3: Passed | J3: 46084 | K3: Adrian
A4: TCID-ZONE-MANAGEMENT-003 | B4: Zone Management | C4: Verify if the number displayed in the Total Zones are accurate | E4: 1. Login to the admin panel 2. Click Zone Management | F4: Email: cardinal.test@cebuana.com Role: Admin | G4: Total zone number accurate; all zones displayed below | H4: As expected | I4: Passed | J4: 46084 | K4: Adrian
A5: TCID-ZONE-MANAGEMENT-004 | B5: Zone Management | C5: Verify if the number displayed in Buildings in Zones are accurate | E5: 1. Login to the admin panel 2. Click Zone Management | F5: Email: cardinal.test@cebuana.com Role: Admin | G5: Data displayed accurate | H5: A building is displayed under a zone but is tagged as unknown | I5: Failed | J5: 46084 | K5: Adrian | L5: PPA-38
A6: TCID-ZONE-MANAGEMENT-005 | B6: Zone Management | C6: Verify if a building can be included in more than one (1) zone | E6: 1. Login to the admin panel 2. Click Zone Management 3. Select and edit a zone 4. Include a building into multiple zones | F6: Email: cardinal.test@cebuana.com Role: Admin | G6: The user can save the changes and it will be reflected on the Zone card "Zone updated" | H6: As expected | I6: Passed | J6: 46084 | K6: Adrian
A7: TCID-ZONE-MANAGEMENT-006 | B7: Zone Management | C7: Verify if users can be added to a zone when editing a zone's details | E7: 1. Login to the admin panel 2. Click Zone Management 3. Select and edit a zone 4. Include a user into multiple zones | F7: Email: cardinal.test@cebuana.com Role: Admin | G7: Users added successfully | H7: As expected | I7: Passed | J7: 46084 | K7: Adrian
A8: TCID-ZONE-MANAGEMENT-007 | B8: Zone Management | C8: Verify if users can be added to multiple zones | E8: 1. Login to the admin panel 2. Click Zone Management 3. Select and edit a zone 4. Include a user into multiple zones | F8: Email: cardinal.test@cebuana.com Role: Admin | G8: Multiple users added successfully | H8: As expected | I8: Passed | J8: 46084 | K8: Adrian
A9: TCID-ZONE-MANAGEMENT-008 | B9: Zone Management | C9: Verify if a user can create a new zone | E9: 1. Login to the admin panel 2. Click Zone Management 3. Click Create Zone 4. Input the zone's name 5. Select buildings from the list provided 6. Select users from the list provided 7. Click Create Zone | F9: Email: cardinal.test@cebuana.com Role: Admin | G9: Zone created successfully | H9: As expected | I9: Passed | J9: 46084 | K9: Adrian
A10: TCID-ZONE-MANAGEMENT-009 | B10: Zone Management | C10: Verify if a user can cancel creating a new zone and the changes won't be saved | E10: 1. Login to the admin panel 2. Click Zone Management 3. Click Create Zone 4. Input the zone's name 5. Select buildings from the list provided 6. Select users from the list provided 7. Click Cancel | F10: Email: cardinal.test@cebuana.com Role: Admin | G10: Workflow cancelled and no changes were saved | H10: As expected | I10: Passed | J10: 46084 | K10: Adrian
A11: TCID-ZONE-MANAGEMENT-010 | B11: Zone Management | C11: Verify if the assigned and unassigned users equals to the total number of users registered in the app | E11: 1. Login to the admin panel 2. Click Zone Management | F11: Email: cardinal.test@cebuana.com Role: Admin | G11: Info accurate Total Users = Assigned Users + Unassigned users | H11: As expected | I11: Passed | J11: 46084 | K11: Adrian
A12: TCID-ZONE-MANAGEMENT-011 | B12: Zone Management | C12: Verify if a user can save a created zone without providing a zone name | E12: 1. Login to the admin panel 2. Click Zone Management 3. Click Create Zone 4. Select buildings from the list provided 5. Select users from the list provided 6. Click Create Zone | F12: Email: cardinal.test@cebuana.com Role: Admin | G12: System will require user to input a zone name Please fill in this field (Zone Name) | H12: As expected | I12: Passed | J12: 46084 | K12: Adrian
A13: TCID-ZONE-MANAGEMENT-012 | B13: Zone Management | C13: Verify if a user can save a created zone without selecting at least one (1) building | E13: 1. Login to the admin panel 2. Click Zone Management 3. Provide a building name 4. Click Create Zone | F13: Email: cardinal.test@cebuana.com Role: Admin | G13: System will require at least one (1) building to be selected Select at least one (1) building | H13: As expected | I13: Passed | J13: 46084 | K13: Adrian
A14: TCID-ZONE-MANAGEMENT-013 | B14: Zone Management | C14: Verify if a user can save a created zone with selected users | E14: 1. Login to the admin panel 2. Click Zone Management 3. Click Create Zone 4. Input the zone's name 5. Select buildings from the list provided 6. Select users from the list provided 7. Click Create Zone | F14: Email: cardinal.test@cebuana.com Role: Admin | G14: Zone created successfully | H14: As expected | I14: Passed | J14: 46084 | K14: Adrian
A15: TCID-ZONE-MANAGEMENT-014 | B15: Zone Management | C15: Verify if a user can save a created zone without selected users | E15: 1. Login to the admin panel 2. Click Zone Management 3. Click Create Zone 4. Input the zone's name 5. Select buildings from the list provided 6. Click Create Zone | F15: Email: cardinal.test@cebuana.com Role: Admin | G15: Zone created successfully | H15: As expected | I15: Passed | J15: 46084 | K15: Adrian
A16: TCID-ZONE-MANAGEMENT-015 | B16: Zone Management | C16: Verify if a zone can be deleted | E16: 1. Login to the admin panel 2. Click Zone Management 3. Click the trash icon in the zone card beside the zone's name | F16: Email: cardinal.test@cebuana.com Role: Admin | G16: Zone deleted successfully | H16: As expected | I16: Passed | J16: 46084 | K16: Adrian

Sheet Building Policies
A1: TEST CASE ID | B1: MODULE | C1: TEST CASE | D1: PREREQUISITES | E1: TEST STEPS | F1: TEST DATA | G1: EXPECTED RESULT | H1: ACTUAL RESULT | I1: STATUS | J1: DATE EXECUTED | K1: TESTER | L1: REMARKS
A2: TCID-BUILDING-POLICIES-001 | B2: Building Policy | C2: Verify if the user can select a specific building to apply a building policy to | E2: 1. Login to the Admin Panel 2. Click Building Policy | G2: Building picker active; dropdown menu will display list of available buildings for selection | H2: As expected | I2: Passed | J2: 46085 | K2: Adrian
A3: TCID-BUILDING-POLICIES-002 | B3: Building Policy | C3: Verify if the list of available policies for implementation will appear once a building has been selected | E3: 1. Login to the Admin Panel 2. Click Building Policy | G3: List of available policies displayed | H3: As expected | I3: Passed | J3: 46085 | K3: Adrian
A4: TCID-BUILDING-POLICIES-003 | B4: Building Policy | C4: Verify if a policy can be enabled | E4: 1. Login to the Admin Panel 2. Click Building Policy 3. Select a policy 4. Click Enable Policy | G4: "Policy enabled" | H4: As expected | I4: Passed | J4: 46085 | K4: Adrian
A5: TCID-BUILDING-POLICIES-004 | B5: Building Policy | C5: Verify if a policy can be disabled | E5: 1. Login to the Admin Panel 2. Click Building Policy 3. Select a policy 4. Click Enabled | G5: "Policy disabled" | H5: As expected | I5: Passed | J5: 46085 | K5: Adrian
A6: TCID-BUILDING-POLICIES-005 | B6: Building Policy | C6: Determine if a user can change the maximum number of users per slot | E6: 1. Login to the Admin Panel 2. Click Building Policy 3. Select a policy 4. Click Enable Policy 5. Input the desired number of users per slot | G6: Policy will be updated | H6: As expected | I6: Passed | J6: 46085 | K6: Adrian
A7: TCID-BUILDING-POLICIES-006 | B7: Building Policy | C7: Verify if a sticker number is required when registering a user to a parking slot when the <Required Sticker> parameter is ON | E7: 1. Login to the Admin Panel 2. Click Building Policy 3. Select a policy 4. Click Enable Policy 5. Set the Required Active parameter to Yes-Required 6. Click Register Users 7. Fill in the necessary details 8. Leave the Sticker Number field blank 9. Click Register | G7: Sticker Number should be a required field. | H7: Sticker Number field is optional | I7: Failed | J7: 46085 | K7: Adrian | L7: PPA-52
A8: TCID-BUILDING-POLICIES-007 | B8: Building Policy | C8: Verify if a sticker number is optional when registering a user to a parking slot when the <Required Sticker> parameter is OFF | E8: 1. Login to the Admin Panel 2. Click Building Policy 3. Select a policy 4. Click Enable Policy 5. Set the Required Active parameter to Yes-Required 6. Click Register Users 7. Fill in the necessary details 8. Click Register | G8: User is registered to a slot successfully | H8: As expected | I8: Passed | J8: 46085 | K8: Adrian
A9: TCID-BUILDING-POLICIES-008 | B9: Building Policy | C9: Verify if a user can be registered to a parking slot when no vehicle on file can be determined | E9: 1. Login to the Admin Panel 2. Click Building Policy 3. Select a policy 4. Click Enable Policy 5. Set the Required Active parameter to Yes-Required 6. Click Register Users 7. Fill in the necessary details 8. Click Register | G9: The user to be registered should have a vehicle attached to their account "This user has no registered vehicles" | H9: As expected | I9: Passed | J9: 46085 | K9: Adrian
A10: TCID-BUILDING-POLICIES-009 | B10: Building Policy | C10: Verify if a user should only be allowed to be registered to one slot only | E10: 1. Login to the Admin Panel 2. Click Building Policy 3. Select a policy 4. Click Enable Policy 5. Set the Required Active parameter to Yes-Required 6. Click Register Users 7. Fill in the necessary details 8. Click Register | G10: Should register User to one slot only | H10: User is registered to multiple slots successfully | I10: Failed | J10: 46085 | K10: Adrian | L10: PPA-53
A11: TCID-BUILDING-POLICIES-010 | B11: Building Policy | C11: Verify if Slot Registrations display the following elements: Total number of registrations Floor numbers Number of reservations per floor Number of slots (per floor) Register User button Dropdown button | E11: 1. Login to the Admin Panel 2. Click Building Policy 3. Select a policy 4. Click Enable Policy | G11: UI elements displayed | H11: As expected | I11: Passed | J11: 46085 | K11: Adrian
A12: TCID-BUILDING-POLICIES-011 | B12: Building Policy | C12: When the user clicks the dropdown menu per each floor, verify if the following elements are displayed in the UI: Slot name User Plate number Sticker Number (if applicable) Total number of users registered per slot Delete icon | E12: 1. Login to the Admin Panel 2. Click Building Policy 3. Select a policy 4. Click Enable Policy 5. Click the dropdown menu icon beside the floor number | G12: UI elements displayed | H12: As expected | I12: Passed | J12: 46085 | K12: Adrian
A13: TCID-BUILDING-POLICIES-012 | B13: Building Policy | C13: Verify if there will be no user details on a slot if there are no users registered to it | E13: 1. Login to the Admin Panel 2. Click Building Policy 3. Select a policy 4. Click Enable Policy 5. Click the dropdown menu icon beside the floor number | G13: "No registrations" | H13: As expected | I13: Passed | J13: 46085 | K13: Adrian
A14: TCID-BUILDING-POLICIES-013 | B14: Building Policy | C14: Verify if a registration can be deleted in a parking slot | E14: 1. Login to the Admin Panel 2. Click Building Policy 3. Select a policy 4. Click Enable Policy 5. Click the dropdown menu icon beside the floor number 6. Click the trash icon to delete the registered user | G14: "Registration revoked" | H14: As expected | I14: Passed | J14: 46085 | K14: Adrian
A15: TCID-BUILDING-POLICIES-014 | B15: Building Policy | C15: Verify if the total number of registrations displayed in the Slot Registrations card will decrease once a registration has been deleted | E15: 1. Login to the Admin Panel 2. Click Building Policy 3. Select a policy 4. Click Enable Policy 5. Click the dropdown menu icon beside the floor number 6. Click the trash icon to delete the registered user | G15: Total number of registrations will be decreased | H15: As expected | I15: Passed | J15: 46085 | K15: Adrian
